<mujoco>

	<asset>
        <texture type="skybox" builtin="gradient" rgb1="0.3 0.5 0.7" rgb2="0 0 0" width="512" height="512"/>

        <texture name="texplane" type="2d" builtin="checker" rgb1=".2 .3 .4" rgb2=".1 0.15 0.2" width="512" height="512" mark="cross" markrgb=".8 .8 .8"/>

        <texture name="texgeom" type="cube" builtin="flat" mark="cross" width="127" height="1278"
            rgb1="0.8 0.6 0.4" rgb2="0.8 0.6 0.4" markrgb="1 1 1" random="0.01"/>

        <material name="matplane" reflectance="0.3" texture="texplane" texrepeat="1 1" texuniform="true"/>

        <material name="matgeom" texture="texgeom" texuniform="true" rgba="0.8 0.6 .4 1"/>
    </asset>

	<worldbody>
		<light diffuse=".5 .5 .5" pos="-20 0 1" dir="1 0 -0.1"/>
		<light diffuse=".5 .5 .5" pos="0 0 20" dir="0 0 -1"/>

		<geom name="floor" pos="0 0 -0.25" size="0 0 .25" type="plane" material="matplane" condim="3"/>
<!--		<geom type="plane" size="1 1 0.1" rgba=".9 0.6 0 1"/>-->
		<body name="wall" pos="1 0 1.25" euler="0 0 0 ">
			<geom type="box" size=".1 2 2" rgba="0 0.6 0.6 1"/>
		</body>

		<body name="car" pos="0 0 0">
			<geom type="box" size="0.1 0.1 0.1" rgba=".9 0.6 0 1"/>
			<joint name="car_acceleration" type="slide" pos="0 0 0" axis="1 0 0"/>
		</body>

	</worldbody>


	 <actuator>
        <motor name="car_acceleration" gear="100" joint="car_acceleration" />
    </actuator>
</mujoco>
